Workbook

Sheet Received
A1: 发送者 | B1: 红包编号\名次 | C1: 1 | D1: 2 | E1: 3 | F1: 总计 | H1: 10 | I1: 20 | J1: 30 | K1: 40 | L1: 50
A2: 钱磊 | B2: 1 | C2: 26.77 | D2: 26.68 | E2: 6.55 | F2: =SUM(C2:E2) -> 60
B3: 2 | C3: 37.01 | D3: 9.89 | E3: 13.1 | F3: =SUM(C3:E3) -> 60
B4: 3 | C4: 19.83 | D4: 23.87 | E4: 16.3 | F4: =SUM(C4:E4) -> 60 | H4: Interval | I4: Count
B5: 4 | C5: 29.88 | D5: 29.48 | E5: 0.64 | F5: =SUM(C5:E5) -> 60 | H5: [00.01,10.00] | I5: 11
B6: 5 | C6: 21.3 | D6: 12.21 | E6: 26.49 | F6: =SUM(C6:E6) -> 60 | H6: [10.01,20.00] | I6: 18
B7: 6 | C7: 22.35 | D7: 28.6 | E7: 9.05 | F7: =SUM(C7:E7) -> 60 | H7: [20.01,30.01] | I7: 17
B8: 7 | C8: 7.17 | D8: 47.27 | E8: 5.56 | F8: =SUM(C8:E8) -> 60 | H8: [30.01,40.00] | I8: 14
B9: 8 | C9: 28.77 | D9: 24.38 | E9: 6.85 | F9: =SUM(C9:E9) -> 60 | H9: [40.01,50.00] | I9: 0
B10: 9 | C10: 10.34 | D10: 31 | E10: 18.66 | F10: =SUM(C10:E10) -> 60 | H10: [50.01,60.00] | I10: 0
B11: 10 | C11: 39.88 | D11: 5.83 | E11: 14.29 | F11: =SUM(C11:E11) -> 60
A12: 徐景骐 | B12: 1 | C12: 38.85 | D12: 17.39 | E12: 3.76 | F12: =SUM(C12:E12) -> 60
B13: 2 | C13: 24.71 | D13: 30.44 | E13: 4.85 | F13: =SUM(C13:E13) -> 60
B14: 3 | C14: 9.11 | D14: 25.66 | E14: 25.23 | F14: =SUM(C14:E14) -> 60
B15: 4 | C15: 13.93 | D15: 44.21 | E15: 1.86 | F15: =SUM(C15:E15) -> 60 | H15: Interval | I15: Count
B16: 5 | C16: 25.77 | D16: 1.71 | E16: 32.52 | F16: =SUM(C16:E16) -> 60 | H16: [00.01,10.00] | I16: 17
B17: 6 | C17: 19.22 | D17: 30.39 | E17: 10.39 | F17: =SUM(C17:E17) -> 60 | H17: [10.01,20.00] | I17: 17
B18: 7 | C18: 21.04 | D18: 3.76 | E18: 35.2 | F18: =SUM(C18:E18) -> 60 | H18: [20.01,30.01] | I18: 13
B19: 8 | C19: 36.14 | D19: 19.25 | E19: 4.61 | F19: =SUM(C19:E19) -> 60 | H19: [30.01,40.00] | I19: 10
B20: 9 | C20: 38.82 | D20: 17.41 | E20: 3.77 | F20: =SUM(C20:E20) -> 60 | H20: [40.01,50.00] | I20: 2
B21: 10 | C21: 18.37 | D21: 14.97 | E21: 26.66 | F21: =SUM(C21:E21) -> 60 | H21: [50.01,60.00] | I21: 1
A22: 钱磊 | B22: 1 | C22: 18.22 | D22: 9.69 | E22: 32.09 | F22: =SUM(C22:E22) -> 60
B23: 2 | C23: 8.78 | D23: 35.12 | E23: 16.1 | F23: =SUM(C23:E23) -> 60
B24: 3 | C24: 14.15 | D24: 2.98 | E24: 42.87 | F24: =SUM(C24:E24) -> 60
B25: 4 | C25: 29.54 | D25: 14.21 | E25: 16.25 | F25: =SUM(C25:E25) -> 60
B26: 5 | C26: 22.21 | D26: 15.4 | E26: 22.39 | F26: =SUM(C26:E26) -> 60 | H26: Interval | I26: Count
B27: 6 | C27: 21.97 | D27: 4.9 | E27: 33.13 | F27: =SUM(C27:E27) -> 60 | H27: [00.01,10.00] | I27: 16
B28: 7 | C28: 13.64 | D28: 14.16 | E28: 32.2 | F28: =SUM(C28:E28) -> 60 | H28: [10.01,20.00] | I28: 23
B29: 8 | C29: 8.37 | D29: 36.48 | E29: 15.15 | F29: =SUM(C29:E29) -> 60 | H29: [20.01,30.01] | I29: 7
B30: 9 | C30: 2.62 | D30: 38.33 | E30: 19.05 | F30: =SUM(C30:E30) -> 60 | H30: [30.01,40.00] | I30: 11
B31: 10 | C31: 36.66 | D31: 6.12 | E31: 17.22 | F31: =SUM(C31:E31) -> 60 | H31: [40.01,50.00] | I31: 2
A32: 徐景骐 | B32: 1 | C32: 15.52 | D32: 17.75 | E32: 26.73 | F32: =SUM(C32:E32) -> 60 | H32: [50.01,60.00] | I32: 1
B33: 2 | C33: 30.49 | D33: 16.69 | E33: 12.82 | F33: =SUM(C33:E33) -> 60
B34: 3 | C34: 19.83 | D34: 16.32 | E34: 23.85 | F34: =SUM(C34:E34) -> 60
B35: 4 | C35: 8.37 | D35: 2.58 | E35: 49.05 | F35: =SUM(C35:E35) -> 60
B36: 5 | C36: 6.75 | D36: 53.1 | E36: 0.15 | F36: =SUM(C36:E36) -> 60
B37: 6 | C37: 26.07 | D37: 23.11 | E37: 10.82 | F37: =SUM(C37:E37) -> 60
B38: 7 | C38: 34.32 | D38: 12.4 | E38: 13.28 | F38: =SUM(C38:E38) -> 60
B39: 8 | C39: 29.84 | D39: 21.09 | E39: 9.07 | F39: =SUM(C39:E39) -> 60
B40: 9 | C40: 25.96 | D40: 16.45 | E40: 17.59 | F40: =SUM(C40:E40) -> 60
...

Sheet TotalLeft
A1: Sender | B1: Red Envelope receive rank | C1: 1 | D1: 2 | E1: 3 | F1: Left
A2: 钱磊 | B2: 1 | C2: 60 | D2: =C2-Received!C2 -> 33.23 | E2: =D2-Received!D2 -> 6.55 | F2: =E2-Received!E2 -> 0
B3: 2 | C3: 60 | D3: =C3-Received!C3 -> 22.99 | E3: =D3-Received!D3 -> 13.1 | F3: =E3-Received!E3 -> 0
B4: 3 | C4: 60 | D4: =C4-Received!C4 -> 40.17 | E4: =D4-Received!D4 -> 16.3 | F4: =E4-Received!E4 -> 0
B5: 4 | C5: 60 | D5: =C5-Received!C5 -> 30.12 | E5: =D5-Received!D5 -> 0.64 | F5: =E5-Received!E5 -> 0
B6: 5 | C6: 60 | D6: =C6-Received!C6 -> 38.7 | E6: =D6-Received!D6 -> 26.49 | F6: =E6-Received!E6 -> 0
B7: 6 | C7: 60 | D7: =C7-Received!C7 -> 37.65 | E7: =D7-Received!D7 -> 9.05 | F7: =E7-Received!E7 -> 0
B8: 7 | C8: 60 | D8: =C8-Received!C8 -> 52.83 | E8: =D8-Received!D8 -> 5.56 | F8: =E8-Received!E8 -> 0
B9: 8 | C9: 60 | D9: =C9-Received!C9 -> 31.23 | E9: =D9-Received!D9 -> 6.85 | F9: =E9-Received!E9 -> 0
B10: 9 | C10: 60 | D10: =C10-Received!C10 -> 49.66 | E10: =D10-Received!D10 -> 18.66 | F10: =E10-Received!E10 -> 0
B11: 10 | C11: 60 | D11: =C11-Received!C11 -> 20.12 | E11: =D11-Received!D11 -> 14.29 | F11: =E11-Received!E11 -> 0
A12: 徐景骐 | B12: 1 | C12: 60 | D12: =C12-Received!C12 -> 21.15 | E12: =D12-Received!D12 -> 3.76 | F12: =E12-Received!E12 -> 0
B13: 2 | C13: 60 | D13: =C13-Received!C13 -> 35.29 | E13: =D13-Received!D13 -> 4.85 | F13: =E13-Received!E13 -> 0
B14: 3 | C14: 60 | D14: =C14-Received!C14 -> 50.89 | E14: =D14-Received!D14 -> 25.23 | F14: =E14-Received!E14 -> 0
B15: 4 | C15: 60 | D15: =C15-Received!C15 -> 46.07 | E15: =D15-Received!D15 -> 1.86 | F15: =E15-Received!E15 -> 0
B16: 5 | C16: 60 | D16: =C16-Received!C16 -> 34.23 | E16: =D16-Received!D16 -> 32.52 | F16: =E16-Received!E16 -> 0
B17: 6 | C17: 60 | D17: =C17-Received!C17 -> 40.78 | E17: =D17-Received!D17 -> 10.39 | F17: =E17-Received!E17 -> 0
B18: 7 | C18: 60 | D18: =C18-Received!C18 -> 38.96 | E18: =D18-Received!D18 -> 35.2 | F18: =E18-Received!E18 -> 0
B19: 8 | C19: 60 | D19: =C19-Received!C19 -> 23.86 | E19: =D19-Received!D19 -> 4.61 | F19: =E19-Received!E19 -> 0
B20: 9 | C20: 60 | D20: =C20-Received!C20 -> 21.18 | E20: =D20-Received!D20 -> 3.77 | F20: =E20-Received!E20 -> 0
B21: 10 | C21: 60 | D21: =C21-Received!C21 -> 41.63 | E21: =D21-Received!D21 -> 26.66 | F21: =E21-Received!E21 -> 0
A22: 钱磊 | B22: 1 | C22: 60 | D22: =C22-Received!C22 -> 41.78 | E22: =D22-Received!D22 -> 32.09 | F22: =E22-Received!E22 -> 0
B23: 2 | C23: 60 | D23: =C23-Received!C23 -> 51.22 | E23: =D23-Received!D23 -> 16.1 | F23: =E23-Received!E23 -> 0
B24: 3 | C24: 60 | D24: =C24-Received!C24 -> 45.85 | E24: =D24-Received!D24 -> 42.87 | F24: =E24-Received!E24 -> 0
B25: 4 | C25: 60 | D25: =C25-Received!C25 -> 30.46 | E25: =D25-Received!D25 -> 16.25 | F25: =E25-Received!E25 -> 0
B26: 5 | C26: 60 | D26: =C26-Received!C26 -> 37.79 | E26: =D26-Received!D26 -> 22.39 | F26: =E26-Received!E26 -> 0
B27: 6 | C27: 60 | D27: =C27-Received!C27 -> 38.03 | E27: =D27-Received!D27 -> 33.13 | F27: =E27-Received!E27 -> 0
B28: 7 | C28: 60 | D28: =C28-Received!C28 -> 46.36 | E28: =D28-Received!D28 -> 32.2 | F28: =E28-Received!E28 -> 0
B29: 8 | C29: 60 | D29: =C29-Received!C29 -> 51.63 | E29: =D29-Received!D29 -> 15.15 | F29: =E29-Received!E29 -> 0
B30: 9 | C30: 60 | D30: =C30-Received!C30 -> 57.38 | E30: =D30-Received!D30 -> 19.05 | F30: =E30-Received!E30 -> 0
B31: 10 | C31: 60 | D31: =C31-Received!C31 -> 23.34 | E31: =D31-Received!D31 -> 17.22 | F31: =E31-Received!E31 -> 0
A32: 徐景骐 | B32: 1 | C32: 60 | D32: =C32-Received!C32 -> 44.48 | E32: =D32-Received!D32 -> 26.73 | F32: =E32-Received!E32 -> 0
B33: 2 | C33: 60 | D33: =C33-Received!C33 -> 29.51 | E33: =D33-Received!D33 -> 12.82 | F33: =E33-Received!E33 -> 0
B34: 3 | C34: 60 | D34: =C34-Received!C34 -> 40.17 | E34: =D34-Received!D34 -> 23.85 | F34: =E34-Received!E34 -> 0
B35: 4 | C35: 60 | D35: =C35-Received!C35 -> 51.63 | E35: =D35-Received!D35 -> 49.05 | F35: =E35-Received!E35 -> 0
B36: 5 | C36: 60 | D36: =C36-Received!C36 -> 53.25 | E36: =D36-Received!D36 -> 0.15 | F36: =E36-Received!E36 -> -1.4155344e-15
B37: 6 | C37: 60 | D37: =C37-Received!C37 -> 33.93 | E37: =D37-Received!D37 -> 10.82 | F37: =E37-Received!E37 -> 0
B38: 7 | C38: 60 | D38: =C38-Received!C38 -> 25.68 | E38: =D38-Received!D38 -> 13.28 | F38: =E38-Received!E38 -> 0
B39: 8 | C39: 60 | D39: =C39-Received!C39 -> 30.16 | E39: =D39-Received!D39 -> 9.07 | F39: =E39-Received!E39 -> 0
B40: 9 | C40: 60 | D40: =C40-Received!C40 -> 34.04 | E40: =D40-Received!D40 -> 17.59 | F40: =E40-Received!E40 -> 0
...
