Workbook

Sheet Received
A1: 发送者 | B1: 红包编号\名次 | C1: 1 | D1: 2 | E1: 3
A2: 钱磊 | B2: 1 | C2: 22.65 | D2: 30.37 | E2: =60-C2-D2 -> 6.98
B3: 2 | C3: 18.72 | D3: 16.26 | E3: =60-C3-D3 -> 25.02
B4: 3 | C4: 11.97 | D4: 28.81 | E4: =60-C4-D4 -> 19.22
B5: 4 | C5: 35.71 | D5: 14.92 | E5: =60-C5-D5 -> 9.37
B6: 5 | C6: 17.93 | D6: 34.89 | E6: =60-C6-D6 -> 7.18
B7: 6 | C7: 35.94 | D7: 17.4 | E7: =60-C7-D7 -> 6.66
B8: 7 | C8: 39.08 | D8: 12.49 | E8: =60-C8-D8 -> 8.43
B9: 8 | C9: 8.61 | D9: 19.34 | E9: =60-C9-D9 -> 32.05
B10: 9 | C10: 3.79 | D10: 23.34 | E10: =60-C10-D10 -> 32.87
B11: 10 | C11: 26.33 | D11: 2.08 | E11: =60-C11-D11 -> 31.59
A12: 徐景骐 | B12: 1 | C12: 7.43 | D12: 25.76 | E12: =60-C12-D12 -> 26.81
B13: 2 | C13: 29.8 | D13: 26.94 | E13: =60-C13-D13 -> 3.26
B14: 3 | C14: 2.82 | D14: 38.36 | E14: =60-C14-D14 -> 18.82
B15: 4 | C15: 8.63 | D15: 13.51 | E15: =60-C15-D15 -> 37.86
B16: 5 | C16: 2.72 | D16: 31.56 | E16: =60-C16-D16 -> 25.72
B17: 6 | C17: 12.06 | D17: 17.9 | E17: =60-C17-D17 -> 30.04
B18: 7 | C18: 11.06 | D18: 22.67 | E18: =60-C18-D18 -> 26.27
B19: 8 | C19: 26.42 | D19: 30.17 | E19: =60-C19-D19 -> 3.41
B20: 9 | C20: 31.67 | D20: 7.66 | E20: =60-C20-D20 -> 20.67
B21: 10 | C21: 31.47 | D21: 16.16 | E21: =60-C21-D21 -> 12.37
A22: 钱磊 | B22: 1 | C22: 10.82 | D22: 18.01 | E22: =60-C22-D22 -> 31.17
B23: 2 | C23: 34.46 | D23: 5.69 | E23: =60-C23-D23 -> 19.85
B24: 3 | C24: 18.67 | D24: 38.72 | E24: =60-C24-D24 -> 2.61
B25: 4 | C25: 11.42 | D25: 8.79 | E25: =60-C25-D25 -> 39.79
B26: 5 | C26: 24.59 | D26: 18.88 | E26: =60-C26-D26 -> 16.53
B27: 6 | C27: 30.34 | D27: 11.82 | E27: =60-C27-D27 -> 17.84
B28: 7 | C28: 18.97 | D28: 25.24 | E28: =60-C28-D28 -> 15.79
B29: 8 | C29: 17.38 | D29: 35.89 | E29: =60-C29-D29 -> 6.73
B30: 9 | C30: 2.74 | D30: 37.88 | E30: =60-C30-D30 -> 19.38
B31: 10 | C31: 23.17 | D31: 5.13 | E31: =60-C31-D31 -> 31.7
A32: 徐景骐 | B32: 1 | C32: 32.68 | D32: 24.19 | E32: 3.13
B33: 2 | C33: 10.37 | D33: 16.89 | E33: =60-C33-D33 -> 32.74
B34: 3 | C34: 18.91 | D34: 7.71 | E34: =60-C34-D34 -> 33.38
B35: 4 | C35: 38.42 | D35: 13.39 | E35: =60-C35-D35 -> 8.19
B36: 5 | C36: 36.05 | D36: 7.18 | E36: =60-C36-D36 -> 16.77
B37: 6 | C37: 26.68 | D37: 10.47 | E37: =60-C37-D37 -> 22.85
B38: 7 | C38: 15.71 | D38: 31.59 | E38: =60-C38-D38 -> 12.7
B39: 8 | C39: 32.29 | D39: 3.22 | E39: =60-C39-D39 -> 24.49
B40: 9 | C40: 32.57 | D40: 14.35 | E40: =60-C40-D40 -> 13.08
...

Sheet Total
A1: 发送者 | B1: 红包编号\名次 | C1: 1 | D1: 2 | E1: 3
A2: 钱磊 | B2: 1 | C2: 60 | D2: =60-Received!C2 -> 37.35 | E2: =D2-Received!D2 -> 6.98 | F2: =E2-Received!E2 -> 0
B3: 2 | C3: 60 | D3: =60-Received!C3 -> 41.28 | E3: =D3-Received!D3 -> 25.02 | F3: =E3-Received!E3 -> 0
B4: 3 | C4: 60 | D4: =60-Received!C4 -> 48.03 | E4: =D4-Received!D4 -> 19.22 | F4: =E4-Received!E4 -> 0
B5: 4 | C5: 60 | D5: =60-Received!C5 -> 24.29 | E5: =D5-Received!D5 -> 9.37 | F5: =E5-Received!E5 -> 0
B6: 5 | C6: 60 | D6: =60-Received!C6 -> 42.07 | E6: =D6-Received!D6 -> 7.18 | F6: =E6-Received!E6 -> 0
B7: 6 | C7: 60 | D7: =60-Received!C7 -> 24.06 | E7: =D7-Received!D7 -> 6.66 | F7: =E7-Received!E7 -> 0
B8: 7 | C8: 60 | D8: =60-Received!C8 -> 20.92 | E8: =D8-Received!D8 -> 8.43 | F8: =E8-Received!E8 -> 0
B9: 8 | C9: 60 | D9: =60-Received!C9 -> 51.39 | E9: =D9-Received!D9 -> 32.05 | F9: =E9-Received!E9 -> 0
B10: 9 | C10: 60 | D10: =60-Received!C10 -> 56.21 | E10: =D10-Received!D10 -> 32.87 | F10: =E10-Received!E10 -> 0
B11: 10 | C11: 60 | D11: =60-Received!C11 -> 33.67 | E11: =D11-Received!D11 -> 31.59 | F11: =E11-Received!E11 -> 0
A12: 徐景骐 | B12: 1 | C12: 60 | D12: =60-Received!C12 -> 52.57 | E12: =D12-Received!D12 -> 26.81 | F12: =E12-Received!E12 -> 0
B13: 2 | C13: 60 | D13: =60-Received!C13 -> 30.2 | E13: =D13-Received!D13 -> 3.26 | F13: =E13-Received!E13 -> 0
B14: 3 | C14: 60 | D14: =60-Received!C14 -> 57.18 | E14: =D14-Received!D14 -> 18.82 | F14: =E14-Received!E14 -> 0
B15: 4 | C15: 60 | D15: =60-Received!C15 -> 51.37 | E15: =D15-Received!D15 -> 37.86 | F15: =E15-Received!E15 -> 0
B16: 5 | C16: 60 | D16: =60-Received!C16 -> 57.28 | E16: =D16-Received!D16 -> 25.72 | F16: =E16-Received!E16 -> 0
B17: 6 | C17: 60 | D17: =60-Received!C17 -> 47.94 | E17: =D17-Received!D17 -> 30.04 | F17: =E17-Received!E17 -> 0
B18: 7 | C18: 60 | D18: =60-Received!C18 -> 48.94 | E18: =D18-Received!D18 -> 26.27 | F18: =E18-Received!E18 -> 0
B19: 8 | C19: 60 | D19: =60-Received!C19 -> 33.58 | E19: =D19-Received!D19 -> 3.41 | F19: =E19-Received!E19 -> 0
B20: 9 | C20: 60 | D20: =60-Received!C20 -> 28.33 | E20: =D20-Received!D20 -> 20.67 | F20: =E20-Received!E20 -> 0
B21: 10 | C21: 60 | D21: =60-Received!C21 -> 28.53 | E21: =D21-Received!D21 -> 12.37 | F21: =E21-Received!E21 -> 0
A22: 钱磊 | B22: 1 | C22: 60 | D22: =60-Received!C22 -> 49.18 | E22: =D22-Received!D22 -> 31.17 | F22: =E22-Received!E22 -> 0
B23: 2 | C23: 60 | D23: =60-Received!C23 -> 25.54 | E23: =D23-Received!D23 -> 19.85 | F23: =E23-Received!E23 -> 0
B24: 3 | C24: 60 | D24: =60-Received!C24 -> 41.33 | E24: =D24-Received!D24 -> 2.61 | F24: =E24-Received!E24 -> 0
B25: 4 | C25: 60 | D25: =60-Received!C25 -> 48.58 | E25: =D25-Received!D25 -> 39.79 | F25: =E25-Received!E25 -> 0
B26: 5 | C26: 60 | D26: =60-Received!C26 -> 35.41 | E26: =D26-Received!D26 -> 16.53 | F26: =E26-Received!E26 -> 0
B27: 6 | C27: 60 | D27: =60-Received!C27 -> 29.66 | E27: =D27-Received!D27 -> 17.84 | F27: =E27-Received!E27 -> 0
B28: 7 | C28: 60 | D28: =60-Received!C28 -> 41.03 | E28: =D28-Received!D28 -> 15.79 | F28: =E28-Received!E28 -> 0
B29: 8 | C29: 60 | D29: =60-Received!C29 -> 42.62 | E29: =D29-Received!D29 -> 6.73 | F29: =E29-Received!E29 -> 0
B30: 9 | C30: 60 | D30: =60-Received!C30 -> 57.26 | E30: =D30-Received!D30 -> 19.38 | F30: =E30-Received!E30 -> 0
B31: 10 | C31: 60 | D31: =60-Received!C31 -> 36.83 | E31: =D31-Received!D31 -> 31.7 | F31: =E31-Received!E31 -> 0
A32: 徐景骐 | B32: 1 | C32: 60 | D32: =60-Received!C32 -> 27.32 | E32: =D32-Received!D32 -> 3.13 | F32: =E32-Received!E32 -> 0
B33: 2 | C33: 60 | D33: =60-Received!C33 -> 49.63 | E33: =D33-Received!D33 -> 32.74 | F33: =E33-Received!E33 -> 0
B34: 3 | C34: 60 | D34: =60-Received!C34 -> 41.09 | E34: =D34-Received!D34 -> 33.38 | F34: =E34-Received!E34 -> 0
B35: 4 | C35: 60 | D35: =60-Received!C35 -> 21.58 | E35: =D35-Received!D35 -> 8.19 | F35: =E35-Received!E35 -> 0
B36: 5 | C36: 60 | D36: =60-Received!C36 -> 23.95 | E36: =D36-Received!D36 -> 16.77 | F36: =E36-Received!E36 -> 0
B37: 6 | C37: 60 | D37: =60-Received!C37 -> 33.32 | E37: =D37-Received!D37 -> 22.85 | F37: =E37-Received!E37 -> 0
B38: 7 | C38: 60 | D38: =60-Received!C38 -> 44.29 | E38: =D38-Received!D38 -> 12.7 | F38: =E38-Received!E38 -> 0
B39: 8 | C39: 60 | D39: =60-Received!C39 -> 27.71 | E39: =D39-Received!D39 -> 24.49 | F39: =E39-Received!E39 -> 0
B40: 9 | C40: 60 | D40: =60-Received!C40 -> 27.43 | E40: =D40-Received!D40 -> 13.08 | F40: =E40-Received!E40 -> 0
...
