Workbook

Sheet Received
B1: 1 | C1: 2 | D1: 3 | E1: 4 | F1: 5 | G1: 6 | H1: 7 | I1: 8 | J1: 9 | K1: 10 | L1: 11 | M1: 12 | N1: 13 | O1: 14 | P1: 15
A2: 钱磊 | B2: 0.06 | C2: 0.04 | D2: 0.02 | E2: 0.04 | F2: 0.05 | G2: 0.03 | H2: 0.01 | I2: 0.02 | J2: 0.01 | K2: 0.05 | L2: 0.01 | M2: 0.07 | N2: 0.11 | O2: 0.03 | P2: 0.05 | Q2: =SUM(B2:P2) -> 0.6
B3: 0.05 | C3: 0.01 | D3: 0.01 | E3: 0.07 | F3: 0.01 | G3: 0.05 | H3: 0.01 | I3: 0.02 | J3: 0.01 | K3: 0.11 | L3: 0.04 | M3: 0.02 | N3: 0.1 | O3: 0.01 | P3: 0.08 | Q3: =SUM(B3:P3) -> 0.6
B4: 0.05 | C4: 0.02 | D4: 0.07 | E4: 0.05 | F4: 0.01 | G4: 0.07 | H4: 0.03 | I4: 0.03 | J4: 0.03 | K4: 0.01 | L4: 0.02 | M4: 0.09 | N4: 0.05 | O4: 0.03 | P4: 0.04 | Q4: =SUM(B4:P4) -> 0.6
B5: 0.03 | C5: 0.06 | D5: 0.02 | E5: 0.02 | F5: 0.03 | G5: 0.02 | H5: 0.01 | I5: 0.08 | J5: 0.01 | K5: 0.01 | L5: 0.01 | M5: 0.04 | N5: 0.01 | O5: 0.01 | P5: 0.24 | Q5: =SUM(B5:P5) -> 0.6
B6: 0.01 | C6: 0.04 | D6: 0.04 | E6: 0.04 | F6: 0.06 | G6: 0.01 | H6: 0.05 | I6: 0.01 | J6: 0.02 | K6: 0.07 | L6: 0.05 | M6: 0.01 | N6: 0.08 | O6: 0.06 | P6: 0.05 | Q6: =SUM(B6:P6) -> 0.6
B7: 0.07 | C7: 0.02 | D7: 0.01 | E7: 0.07 | F7: 0.01 | G7: 0.05 | H7: 0.07 | I7: 0.01 | J7: 0.07 | K7: 0.01 | L7: 0.01 | M7: 0.02 | N7: 0.01 | O7: 0.03 | P7: 0.14 | Q7: =SUM(B7:P7) -> 0.6
B8: 0.04 | C8: 0.02 | D8: 0.01 | E8: 0.06 | F8: 0.01 | G8: 0.03 | H8: 0.04 | I8: 0.06 | J8: 0.01 | K8: 0.07 | L8: 0.07 | M8: 0.02 | N8: 0.06 | O8: 0.03 | P8: 0.07 | Q8: =SUM(B8:P8) -> 0.6
B9: 0.03 | C9: 0.06 | D9: 0.04 | E9: 0.02 | F9: 0.05 | G9: 0.03 | H9: 0.04 | I9: 0.01 | J9: 0.01 | K9: 0.07 | L9: 0.02 | M9: 0.02 | N9: 0.06 | O9: 0.01 | P9: 0.13 | Q9: =SUM(B9:P9) -> 0.6
B10: 0.03 | C10: 0.01 | D10: 0.03 | E10: 0.06 | F10: 0.07 | G10: 0.04 | H10: 0.03 | I10: 0.05 | J10: 0.04 | K10: 0.01 | L10: 0.03 | M10: 0.03 | N10: 0.09 | O10: 0.01 | P10: 0.07 | Q10: =SUM(B10:P10) -> 0.6
B11: 0.01 | C11: 0.02 | D11: 0.02 | E11: 0.03 | F11: 0.01 | G11: 0.05 | H11: 0.04 | I11: 0.05 | J11: 0.01 | K11: 0.02 | L11: 0.09 | M11: 0.11 | N11: 0.05 | O11: 0.07 | P11: 0.02 | Q11: =SUM(B11:P11) -> 0.6
A12: 沈思弦 | B12: 0.04 | C12: 0.06 | D12: 0.01 | E12: 0.03 | F12: 0.05 | G12: 0.06 | H12: 0.05 | I12: 0.01 | J12: 0.01 | K12: 0.01 | L12: 0.06 | M12: 0.09 | N12: 0.06 | O12: 0.03 | P12: 0.03 | Q12: =SUM(B12:P12) -> 0.6
B13: 0.03 | C13: 0.01 | D13: 0.01 | E13: 0.07 | F13: 0.06 | G13: 0.01 | H13: 0.07 | I13: 0.01 | J13: 0.01 | K13: 0.09 | L13: 0.07 | M13: 0.02 | N13: 0.02 | O13: 0.01 | P13: 0.11 | Q13: =SUM(B13:P13) -> 0.6
B14: 0.04 | C14: 0.01 | D14: 0.02 | E14: 0.05 | F14: 0.05 | G14: 0.07 | H14: 0.03 | I14: 0.02 | J14: 0.03 | K14: 0.01 | L14: 0.05 | M14: 0.07 | N14: 0.05 | O14: 0.07 | P14: 0.03 | Q14: =SUM(B14:P14) -> 0.6
B15: 0.02 | C15: 0.02 | D15: 0.02 | E15: 0.05 | F15: 0.01 | G15: 0.02 | H15: 0.02 | I15: 0.08 | J15: 0.01 | K15: 0.06 | L15: 0.01 | M15: 0.09 | N15: 0.01 | O15: 0.13 | P15: 0.05 | Q15: =SUM(B15:P15) -> 0.6
B16: 0.06 | C16: 0.04 | D16: 0.01 | E16: 0.01 | F16: 0.03 | G16: 0.06 | H16: 0.06 | I16: 0.03 | J16: 0.01 | K16: 0.07 | L16: 0.02 | M16: 0.08 | N16: 0.01 | O16: 0.02 | P16: 0.09 | Q16: =SUM(B16:P16) -> 0.6
B17: 0.04 | C17: 0.04 | D17: 0.02 | E17: 0.04 | F17: 0.07 | G17: 0.04 | H17: 0.02 | I17: 0.06 | J17: 0.03 | K17: 0.01 | L17: 0.01 | M17: 0.05 | N17: 0.01 | O17: 0.01 | P17: 0.15 | Q17: =SUM(B17:P17) -> 0.6
B18: 0.07 | C18: 0.01 | D18: 0.01 | E18: 0.01 | F18: 0.06 | G18: 0.04 | H18: 0.01 | I18: 0.02 | J18: 0.04 | K18: 0.03 | L18: 0.1 | M18: 0.03 | N18: 0.09 | O18: 0.02 | P18: 0.06 | Q18: =SUM(B18:P18) -> 0.6
B19: 0.04 | C19: 0.01 | D19: 0.01 | E19: 0.07 | F19: 0.05 | G19: 0.04 | H19: 0.03 | I19: 0.01 | J19: 0.04 | K19: 0.01 | L19: 0.05 | M19: 0.05 | N19: 0.05 | O19: 0.06 | P19: 0.08 | Q19: =SUM(B19:P19) -> 0.6
B20: 0.06 | C20: 0.05 | D20: 0.01 | E20: 0.07 | F20: 0.01 | G20: 0.06 | H20: 0.01 | I20: 0.01 | J20: 0.07 | K20: 0.03 | L20: 0.01 | M20: 0.06 | N20: 0.01 | O20: 0.03 | P20: 0.11 | Q20: =SUM(B20:P20) -> 0.6
B21: 0.02 | C21: 0.06 | D21: 0.04 | E21: 0.05 | F21: 0.04 | G21: 0.01 | H21: 0.03 | I21: 0.06 | J21: 0.07 | K21: 0.02 | L21: 0.06 | M21: 0.01 | N21: 0.01 | O21: 0.07 | P21: 0.05 | Q21: =SUM(B21:P21) -> 0.6
A22: 林子修 | B22: 0.02 | C22: 0.03 | D22: 0.01 | E22: 0.02 | F22: 0.05 | G22: 0.06 | H22: 0.05 | I22: 0.01 | J22: 0.06 | K22: 0.01 | L22: 0.02 | M22: 0.07 | N22: 0.01 | O22: 0.07 | P22: 0.11 | Q22: =SUM(B22:P22) -> 0.6
B23: 0.05 | C23: 0.01 | D23: 0.03 | E23: 0.04 | F23: 0.05 | G23: 0.02 | H23: 0.04 | I23: 0.01 | J23: 0.03 | K23: 0.01 | L23: 0.09 | M23: 0.02 | N23: 0.01 | O23: 0.01 | P23: 0.18 | Q23: =SUM(B23:P23) -> 0.6
B24: 0.02 | C24: 0.06 | D24: 0.07 | E24: 0.02 | F24: 0.02 | G24: 0.05 | H24: 0.01 | I24: 0.03 | J24: 0.03 | K24: 0.03 | L24: 0.08 | M24: 0.02 | N24: 0.02 | O24: 0.02 | P24: 0.12 | Q24: =SUM(B24:P24) -> 0.6
B25: 0.05 | C25: 0.04 | D25: 0.02 | E25: 0.06 | F25: 0.01 | G25: 0.05 | H25: 0.07 | I25: 0.02 | J25: 0.02 | K25: 0.01 | L25: 0.01 | M25: 0.03 | N25: 0.13 | O25: 0.06 | P25: 0.02 | Q25: =SUM(B25:P25) -> 0.6
B26: 0.01 | C26: 0.04 | D26: 0.02 | E26: 0.05 | F26: 0.01 | G26: 0.01 | H26: 0.06 | I26: 0.02 | J26: 0.03 | K26: 0.03 | L26: 0.02 | M26: 0.06 | N26: 0.08 | O26: 0.1 | P26: 0.06 | Q26: =SUM(B26:P26) -> 0.6
B27: 0.07 | C27: 0.01 | D27: 0.03 | E27: 0.01 | F27: 0.01 | G27: 0.01 | H27: 0.07 | I27: 0.05 | J27: 0.04 | K27: 0.01 | L27: 0.01 | M27: 0.01 | N27: 0.17 | O27: 0.06 | P27: 0.04 | Q27: =SUM(B27:P27) -> 0.6
B28: 0.07 | C28: 0.02 | D28: 0.03 | E28: 0.01 | F28: 0.04 | G28: 0.01 | H28: 0.02 | I28: 0.04 | J28: 0.01 | K28: 0.09 | L28: 0.04 | M28: 0.08 | N28: 0.01 | O28: 0.1 | P28: 0.03 | Q28: =SUM(B28:P28) -> 0.6
B29: 0.01 | C29: 0.05 | D29: 0.06 | E29: 0.01 | F29: 0.02 | G29: 0.05 | H29: 0.05 | I29: 0.01 | J29: 0.04 | K29: 0.09 | L29: 0.06 | M29: 0.03 | N29: 0.02 | O29: 0.05 | P29: 0.05 | Q29: =SUM(B29:P29) -> 0.6
B30: 0.01 | C30: 0.01 | D30: 0.02 | E30: 0.07 | F30: 0.06 | G30: 0.01 | H30: 0.07 | I30: 0.01 | J30: 0.04 | K30: 0.06 | L30: 0.02 | M30: 0.02 | N30: 0.1 | O30: 0.01 | P30: 0.09 | Q30: =SUM(B30:P30) -> 0.6
B31: 0.01 | C31: 0.06 | D31: 0.07 | E31: 0.02 | F31: 0.03 | G31: 0.06 | H31: 0.01 | I31: 0.06 | J31: 0.06 | K31: 0.01 | L31: 0.01 | M31: 0.08 | N31: 0.05 | O31: 0.02 | P31: 0.05 | Q31: =SUM(B31:P31) -> 0.6
A32: 李墨涵 | B32: 0.05 | C32: 0.01 | D32: 0.03 | E32: 0.03 | F32: 0.05 | G32: 0.05 | H32: 0.03 | I32: 0.05 | J32: 0.04 | K32: 0.05 | L32: 0.06 | M32: 0.04 | N32: 0.02 | O32: 0.03 | P32: 0.06 | Q32: =SUM(B32:P32) -> 0.6
B33: 0.06 | C33: 0.04 | D33: 0.01 | E33: 0.03 | F33: 0.04 | G33: 0.03 | H33: 0.06 | I33: 0.04 | J33: 0.04 | K33: 0.04 | L33: 0.04 | M33: 0.06 | N33: 0.03 | O33: 0.01 | P33: 0.07 | Q33: =SUM(B33:P33) -> 0.6
B34: 0.01 | C34: 0.05 | D34: 0.07 | E34: 0.03 | F34: 0.03 | G34: 0.01 | H34: 0.04 | I34: 0.01 | J34: 0.08 | K34: 0.05 | L34: 0.03 | M34: 0.01 | N34: 0.04 | O34: 0.09 | P34: 0.05 | Q34: =SUM(B34:P34) -> 0.6
B35: 0.05 | C35: 0.01 | D35: 0.04 | E35: 0.04 | F35: 0.02 | G35: 0.03 | H35: 0.06 | I35: 0.06 | J35: 0.02 | K35: 0.01 | L35: 0.07 | M35: 0.03 | N35: 0.09 | O35: 0.03 | P35: 0.04 | Q35: =SUM(B35:P35) -> 0.6
B36: 0.03 | C36: 0.03 | D36: 0.04 | E36: 0.05 | F36: 0.06 | G36: 0.03 | H36: 0.06 | I36: 0.04 | J36: 0.05 | K36: 0.02 | L36: 0.05 | M36: 0.01 | N36: 0.03 | O36: 0.04 | P36: 0.06 | Q36: =SUM(B36:P36) -> 0.6
B37: 0.04 | C37: 0.04 | D37: 0.01 | E37: 0.01 | F37: 0.06 | G37: 0.03 | H37: 0.01 | I37: 0.01 | J37: 0.05 | K37: 0.08 | L37: 0.07 | M37: 0.07 | N37: 0.04 | O37: 0.02 | P37: 0.06 | Q37: =SUM(B37:P37) -> 0.6
B38: 0.05 | C38: 0.02 | D38: 0.07 | E38: 0.04 | F38: 0.04 | G38: 0.03 | H38: 0.01 | I38: 0.07 | J38: 0.05 | K38: 0.01 | L38: 0.01 | M38: 0.09 | N38: 0.04 | O38: 0.05 | P38: 0.02 | Q38: =SUM(B38:P38) -> 0.6
B39: 0.01 | C39: 0.03 | D39: 0.07 | E39: 0.01 | F39: 0.03 | G39: 0.07 | H39: 0.01 | I39: 0.02 | J39: 0.09 | K39: 0.01 | L39: 0.01 | M39: 0.04 | N39: 0.03 | O39: 0.13 | P39: 0.04 | Q39: =SUM(B39:P39) -> 0.6
B40: 0.07 | C40: 0.01 | D40: 0.02 | E40: 0.04 | F40: 0.01 | G40: 0.03 | H40: 0.05 | I40: 0.04 | J40: 0.05 | K40: 0.06 | L40: 0.02 | M40: 0.02 | N40: 0.06 | O40: 0.04 | P40: 0.08 | Q40: =SUM(B40:P40) -> 0.6
...

Sheet Total
B1: 1 | C1: 2 | D1: 3 | E1: 4 | F1: 5 | G1: 6 | H1: 7 | I1: 8 | J1: 9 | K1: 10 | L1: 11 | M1: 12 | N1: 13 | O1: 14 | P1: 15 | Q1: Money left
A2: 钱磊 | B2: 0.6 | C2: =B2-Received!B2 -> 0.54 | D2: =C2-Received!C2 -> 0.5 | E2: =D2-Received!D2 -> 0.48 | F2: =E2-Received!E2 -> 0.44 | G2: =F2-Received!F2 -> 0.39 | H2: =G2-Received!G2 -> 0.36 | I2: =H2-Received!H2 -> 0.35 | J2: =I2-Received!I2 -> 0.33 | ... Q2: =P2-Received!P2 -> -5.5511151e-17
B3: 0.6 | C3: =B3-Received!B3 -> 0.55 | D3: =C3-Received!C3 -> 0.54 | E3: =D3-Received!D3 -> 0.53 | F3: =E3-Received!E3 -> 0.46 | G3: =F3-Received!F3 -> 0.45 | H3: =G3-Received!G3 -> 0.4 | I3: =H3-Received!H3 -> 0.39 | J3: =I3-Received!I3 -> 0.37 | ... Q3: =P3-Received!P3 -> -1.110223e-16
B4: 0.6 | C4: =B4-Received!B4 -> 0.55 | D4: =C4-Received!C4 -> 0.53 | E4: =D4-Received!D4 -> 0.46 | F4: =E4-Received!E4 -> 0.41 | G4: =F4-Received!F4 -> 0.4 | H4: =G4-Received!G4 -> 0.33 | I4: =H4-Received!H4 -> 0.3 | J4: =I4-Received!I4 -> 0.27 | ... Q4: =P4-Received!P4 -> -9.0205621e-17
B5: 0.6 | C5: =B5-Received!B5 -> 0.57 | D5: =C5-Received!C5 -> 0.51 | E5: =D5-Received!D5 -> 0.49 | F5: =E5-Received!E5 -> 0.47 | G5: =F5-Received!F5 -> 0.44 | H5: =G5-Received!G5 -> 0.42 | I5: =H5-Received!H5 -> 0.41 | J5: =I5-Received!I5 -> 0.33 | ... Q5: =P5-Received!P5 -> 0
B6: 0.6 | C6: =B6-Received!B6 -> 0.59 | D6: =C6-Received!C6 -> 0.55 | E6: =D6-Received!D6 -> 0.51 | F6: =E6-Received!E6 -> 0.47 | G6: =F6-Received!F6 -> 0.41 | H6: =G6-Received!G6 -> 0.4 | I6: =H6-Received!H6 -> 0.35 | J6: =I6-Received!I6 -> 0.34 | ... Q6: =P6-Received!P6 -> -1.110223e-16
B7: 0.6 | C7: =B7-Received!B7 -> 0.53 | D7: =C7-Received!C7 -> 0.51 | E7: =D7-Received!D7 -> 0.5 | F7: =E7-Received!E7 -> 0.43 | G7: =F7-Received!F7 -> 0.42 | H7: =G7-Received!G7 -> 0.37 | I7: =H7-Received!H7 -> 0.3 | J7: =I7-Received!I7 -> 0.29 | ... Q7: =P7-Received!P7 -> 0
B8: 0.6 | C8: =B8-Received!B8 -> 0.56 | D8: =C8-Received!C8 -> 0.54 | E8: =D8-Received!D8 -> 0.53 | F8: =E8-Received!E8 -> 0.47 | G8: =F8-Received!F8 -> 0.46 | H8: =G8-Received!G8 -> 0.43 | I8: =H8-Received!H8 -> 0.39 | J8: =I8-Received!I8 -> 0.33 | ... Q8: =P8-Received!P8 -> 0
B9: 0.6 | C9: =B9-Received!B9 -> 0.57 | D9: =C9-Received!C9 -> 0.51 | E9: =D9-Received!D9 -> 0.47 | F9: =E9-Received!E9 -> 0.45 | G9: =F9-Received!F9 -> 0.4 | H9: =G9-Received!G9 -> 0.37 | I9: =H9-Received!H9 -> 0.33 | J9: =I9-Received!I9 -> 0.32 | ... Q9: =P9-Received!P9 -> 0
B10: 0.6 | C10: =B10-Received!B10 -> 0.57 | D10: =C10-Received!C10 -> 0.56 | E10: =D10-Received!D10 -> 0.53 | F10: =E10-Received!E10 -> 0.47 | G10: =F10-Received!F10 -> 0.4 | H10: =G10-Received!G10 -> 0.36 | I10: =H10-Received!H10 -> 0.33 | J10: =I10-Received!I10 -> 0.28 | ... Q10: =P10-Received!P10 -> 0
B11: 0.6 | C11: =B11-Received!B11 -> 0.59 | D11: =C11-Received!C11 -> 0.57 | E11: =D11-Received!D11 -> 0.55 | F11: =E11-Received!E11 -> 0.52 | G11: =F11-Received!F11 -> 0.51 | H11: =G11-Received!G11 -> 0.46 | I11: =H11-Received!H11 -> 0.42 | J11: =I11-Received!I11 -> 0.37 | ... Q11: =P11-Received!P11 -> -1.0755286e-16
A12: 沈思弦 | B12: 0.6 | C12: =B12-Received!B12 -> 0.56 | D12: =C12-Received!C12 -> 0.5 | E12: =D12-Received!D12 -> 0.49 | F12: =E12-Received!E12 -> 0.46 | G12: =F12-Received!F12 -> 0.41 | H12: =G12-Received!G12 -> 0.35 | I12: =H12-Received!H12 -> 0.3 | J12: =I12-Received!I12 -> 0.29 | ... Q12: =P12-Received!P12 -> -2.7755576e-17
B13: 0.6 | C13: =B13-Received!B13 -> 0.57 | D13: =C13-Received!C13 -> 0.56 | E13: =D13-Received!D13 -> 0.55 | F13: =E13-Received!E13 -> 0.48 | G13: =F13-Received!F13 -> 0.42 | H13: =G13-Received!G13 -> 0.41 | I13: =H13-Received!H13 -> 0.34 | J13: =I13-Received!I13 -> 0.33 | ... Q13: =P13-Received!P13 -> 0
B14: 0.6 | C14: =B14-Received!B14 -> 0.56 | D14: =C14-Received!C14 -> 0.55 | E14: =D14-Received!D14 -> 0.53 | F14: =E14-Received!E14 -> 0.48 | G14: =F14-Received!F14 -> 0.43 | H14: =G14-Received!G14 -> 0.36 | I14: =H14-Received!H14 -> 0.33 | J14: =I14-Received!I14 -> 0.31 | ... Q14: =P14-Received!P14 -> -9.7144515e-17
B15: 0.6 | C15: =B15-Received!B15 -> 0.58 | D15: =C15-Received!C15 -> 0.56 | E15: =D15-Received!D15 -> 0.54 | F15: =E15-Received!E15 -> 0.49 | G15: =F15-Received!F15 -> 0.48 | H15: =G15-Received!G15 -> 0.46 | I15: =H15-Received!H15 -> 0.44 | J15: =I15-Received!I15 -> 0.36 | ... Q15: =P15-Received!P15 -> -1.5265567e-16
B16: 0.6 | C16: =B16-Received!B16 -> 0.54 | D16: =C16-Received!C16 -> 0.5 | E16: =D16-Received!D16 -> 0.49 | F16: =E16-Received!E16 -> 0.48 | G16: =F16-Received!F16 -> 0.45 | H16: =G16-Received!G16 -> 0.39 | I16: =H16-Received!H16 -> 0.33 | J16: =I16-Received!I16 -> 0.3 | ... Q16: =P16-Received!P16 -> 0
B17: 0.6 | C17: =B17-Received!B17 -> 0.56 | D17: =C17-Received!C17 -> 0.52 | E17: =D17-Received!D17 -> 0.5 | F17: =E17-Received!E17 -> 0.46 | G17: =F17-Received!F17 -> 0.39 | H17: =G17-Received!G17 -> 0.35 | I17: =H17-Received!H17 -> 0.33 | J17: =I17-Received!I17 -> 0.27 | ... Q17: =P17-Received!P17 -> 0
B18: 0.6 | C18: =B18-Received!B18 -> 0.53 | D18: =C18-Received!C18 -> 0.52 | E18: =D18-Received!D18 -> 0.51 | F18: =E18-Received!E18 -> 0.5 | G18: =F18-Received!F18 -> 0.44 | H18: =G18-Received!G18 -> 0.4 | I18: =H18-Received!H18 -> 0.39 | J18: =I18-Received!I18 -> 0.37 | ... Q18: =P18-Received!P18 -> 0
B19: 0.6 | C19: =B19-Received!B19 -> 0.56 | D19: =C19-Received!C19 -> 0.55 | E19: =D19-Received!D19 -> 0.54 | F19: =E19-Received!E19 -> 0.47 | G19: =F19-Received!F19 -> 0.42 | H19: =G19-Received!G19 -> 0.38 | I19: =H19-Received!H19 -> 0.35 | J19: =I19-Received!I19 -> 0.34 | ... Q19: =P19-Received!P19 -> 0
B20: 0.6 | C20: =B20-Received!B20 -> 0.54 | D20: =C20-Received!C20 -> 0.49 | E20: =D20-Received!D20 -> 0.48 | F20: =E20-Received!E20 -> 0.41 | G20: =F20-Received!F20 -> 0.4 | H20: =G20-Received!G20 -> 0.34 | I20: =H20-Received!H20 -> 0.33 | J20: =I20-Received!I20 -> 0.32 | ... Q20: =P20-Received!P20 -> 0
B21: 0.6 | C21: =B21-Received!B21 -> 0.58 | D21: =C21-Received!C21 -> 0.52 | E21: =D21-Received!D21 -> 0.48 | F21: =E21-Received!E21 -> 0.43 | G21: =F21-Received!F21 -> 0.39 | H21: =G21-Received!G21 -> 0.38 | I21: =H21-Received!H21 -> 0.35 | J21: =I21-Received!I21 -> 0.29 | ... Q21: =P21-Received!P21 -> 8.3266727e-17
A22: 林子修 | B22: 0.6 | C22: =B22-Received!B22 -> 0.58 | D22: =C22-Received!C22 -> 0.55 | E22: =D22-Received!D22 -> 0.54 | F22: =E22-Received!E22 -> 0.52 | G22: =F22-Received!F22 -> 0.47 | H22: =G22-Received!G22 -> 0.41 | I22: =H22-Received!H22 -> 0.36 | J22: =I22-Received!I22 -> 0.35 | ... Q22: =P22-Received!P22 -> -1.2490009e-16
B23: 0.6 | C23: =B23-Received!B23 -> 0.55 | D23: =C23-Received!C23 -> 0.54 | E23: =D23-Received!D23 -> 0.51 | F23: =E23-Received!E23 -> 0.47 | G23: =F23-Received!F23 -> 0.42 | H23: =G23-Received!G23 -> 0.4 | I23: =H23-Received!H23 -> 0.36 | J23: =I23-Received!I23 -> 0.35 | ... Q23: =P23-Received!P23 -> 0
B24: 0.6 | C24: =B24-Received!B24 -> 0.58 | D24: =C24-Received!C24 -> 0.52 | E24: =D24-Received!D24 -> 0.45 | F24: =E24-Received!E24 -> 0.43 | G24: =F24-Received!F24 -> 0.41 | H24: =G24-Received!G24 -> 0.36 | I24: =H24-Received!H24 -> 0.35 | J24: =I24-Received!I24 -> 0.32 | ... Q24: =P24-Received!P24 -> 0
B25: 0.6 | C25: =B25-Received!B25 -> 0.55 | D25: =C25-Received!C25 -> 0.51 | E25: =D25-Received!D25 -> 0.49 | F25: =E25-Received!E25 -> 0.43 | G25: =F25-Received!F25 -> 0.42 | H25: =G25-Received!G25 -> 0.37 | I25: =H25-Received!H25 -> 0.3 | J25: =I25-Received!I25 -> 0.28 | ... Q25: =P25-Received!P25 -> -1.7694179e-16
B26: 0.6 | C26: =B26-Received!B26 -> 0.59 | D26: =C26-Received!C26 -> 0.55 | E26: =D26-Received!D26 -> 0.53 | F26: =E26-Received!E26 -> 0.48 | G26: =F26-Received!F26 -> 0.47 | H26: =G26-Received!G26 -> 0.46 | I26: =H26-Received!H26 -> 0.4 | J26: =I26-Received!I26 -> 0.38 | ... Q26: =P26-Received!P26 -> -1.9428903e-16
B27: 0.6 | C27: =B27-Received!B27 -> 0.53 | D27: =C27-Received!C27 -> 0.52 | E27: =D27-Received!D27 -> 0.49 | F27: =E27-Received!E27 -> 0.48 | G27: =F27-Received!F27 -> 0.47 | H27: =G27-Received!G27 -> 0.46 | I27: =H27-Received!H27 -> 0.39 | J27: =I27-Received!I27 -> 0.34 | ... Q27: =P27-Received!P27 -> 0
B28: 0.6 | C28: =B28-Received!B28 -> 0.53 | D28: =C28-Received!C28 -> 0.51 | E28: =D28-Received!D28 -> 0.48 | F28: =E28-Received!E28 -> 0.47 | G28: =F28-Received!F28 -> 0.43 | H28: =G28-Received!G28 -> 0.42 | I28: =H28-Received!H28 -> 0.4 | J28: =I28-Received!I28 -> 0.36 | ... Q28: =P28-Received!P28 -> 0
B29: 0.6 | C29: =B29-Received!B29 -> 0.59 | D29: =C29-Received!C29 -> 0.54 | E29: =D29-Received!D29 -> 0.48 | F29: =E29-Received!E29 -> 0.47 | G29: =F29-Received!F29 -> 0.45 | H29: =G29-Received!G29 -> 0.4 | I29: =H29-Received!H29 -> 0.35 | J29: =I29-Received!I29 -> 0.34 | ... Q29: =P29-Received!P29 -> -6.9388939e-17
B30: 0.6 | C30: =B30-Received!B30 -> 0.59 | D30: =C30-Received!C30 -> 0.58 | E30: =D30-Received!D30 -> 0.56 | F30: =E30-Received!E30 -> 0.49 | G30: =F30-Received!F30 -> 0.43 | H30: =G30-Received!G30 -> 0.42 | I30: =H30-Received!H30 -> 0.35 | J30: =I30-Received!I30 -> 0.34 | ... Q30: =P30-Received!P30 -> 0
B31: 0.6 | C31: =B31-Received!B31 -> 0.59 | D31: =C31-Received!C31 -> 0.53 | E31: =D31-Received!D31 -> 0.46 | F31: =E31-Received!E31 -> 0.44 | G31: =F31-Received!F31 -> 0.41 | H31: =G31-Received!G31 -> 0.35 | I31: =H31-Received!H31 -> 0.34 | J31: =I31-Received!I31 -> 0.28 | ... Q31: =P31-Received!P31 -> 0
A32: 李墨涵 | B32: 0.6 | C32: =B32-Received!B32 -> 0.55 | D32: =C32-Received!C32 -> 0.54 | E32: =D32-Received!D32 -> 0.51 | F32: =E32-Received!E32 -> 0.48 | G32: =F32-Received!F32 -> 0.43 | H32: =G32-Received!G32 -> 0.38 | I32: =H32-Received!H32 -> 0.35 | J32: =I32-Received!I32 -> 0.3 | ... Q32: =P32-Received!P32 -> -9.7144515e-17
B33: 0.6 | C33: =B33-Received!B33 -> 0.54 | D33: =C33-Received!C33 -> 0.5 | E33: =D33-Received!D33 -> 0.49 | F33: =E33-Received!E33 -> 0.46 | G33: =F33-Received!F33 -> 0.42 | H33: =G33-Received!G33 -> 0.39 | I33: =H33-Received!H33 -> 0.33 | J33: =I33-Received!I33 -> 0.29 | ... Q33: =P33-Received!P33 -> 0
B34: 0.6 | C34: =B34-Received!B34 -> 0.59 | D34: =C34-Received!C34 -> 0.54 | E34: =D34-Received!D34 -> 0.47 | F34: =E34-Received!E34 -> 0.44 | G34: =F34-Received!F34 -> 0.41 | H34: =G34-Received!G34 -> 0.4 | I34: =H34-Received!H34 -> 0.36 | J34: =I34-Received!I34 -> 0.35 | ... Q34: =P34-Received!P34 -> -9.7144515e-17
B35: 0.6 | C35: =B35-Received!B35 -> 0.55 | D35: =C35-Received!C35 -> 0.54 | E35: =D35-Received!D35 -> 0.5 | F35: =E35-Received!E35 -> 0.46 | G35: =F35-Received!F35 -> 0.44 | H35: =G35-Received!G35 -> 0.41 | I35: =H35-Received!H35 -> 0.35 | J35: =I35-Received!I35 -> 0.29 | ... Q35: =P35-Received!P35 -> -1.0408341e-16
B36: 0.6 | C36: =B36-Received!B36 -> 0.57 | D36: =C36-Received!C36 -> 0.54 | E36: =D36-Received!D36 -> 0.5 | F36: =E36-Received!E36 -> 0.45 | G36: =F36-Received!F36 -> 0.39 | H36: =G36-Received!G36 -> 0.36 | I36: =H36-Received!H36 -> 0.3 | J36: =I36-Received!I36 -> 0.26 | ... Q36: =P36-Received!P36 -> 0
B37: 0.6 | C37: =B37-Received!B37 -> 0.56 | D37: =C37-Received!C37 -> 0.52 | E37: =D37-Received!D37 -> 0.51 | F37: =E37-Received!E37 -> 0.5 | G37: =F37-Received!F37 -> 0.44 | H37: =G37-Received!G37 -> 0.41 | I37: =H37-Received!H37 -> 0.4 | J37: =I37-Received!I37 -> 0.39 | ... Q37: =P37-Received!P37 -> -1.2490009e-16
B38: 0.6 | C38: =B38-Received!B38 -> 0.55 | D38: =C38-Received!C38 -> 0.53 | E38: =D38-Received!D38 -> 0.46 | F38: =E38-Received!E38 -> 0.42 | G38: =F38-Received!F38 -> 0.38 | H38: =G38-Received!G38 -> 0.35 | I38: =H38-Received!H38 -> 0.34 | J38: =I38-Received!I38 -> 0.27 | ... Q38: =P38-Received!P38 -> -5.2041704e-17
B39: 0.6 | C39: =B39-Received!B39 -> 0.59 | D39: =C39-Received!C39 -> 0.56 | E39: =D39-Received!D39 -> 0.49 | F39: =E39-Received!E39 -> 0.48 | G39: =F39-Received!F39 -> 0.45 | H39: =G39-Received!G39 -> 0.38 | I39: =H39-Received!H39 -> 0.37 | J39: =I39-Received!I39 -> 0.35 | ... Q39: =P39-Received!P39 -> -1.3183898e-16
B40: 0.6 | C40: =B40-Received!B40 -> 0.53 | D40: =C40-Received!C40 -> 0.52 | E40: =D40-Received!D40 -> 0.5 | F40: =E40-Received!E40 -> 0.46 | G40: =F40-Received!F40 -> 0.45 | H40: =G40-Received!G40 -> 0.42 | I40: =H40-Received!H40 -> 0.37 | J40: =I40-Received!I40 -> 0.33 | ... Q40: =P40-Received!P40 -> 0
...
